Workbook

Sheet 1. Missing Value Summary
A1: Missing Value Summary
A3: Column Evaluated | B3: Missing Count | C3: Handling Strategy Applied
A4: Region | B4: =COUNTIF('Cleaned Orders'!AC:AC, "Missing region") -> 24 | C4: Blanks replaced with "Unknown" and flagged.
A5: Ship Mode | B5: =COUNTIF('Cleaned Orders'!AC:AC, "Missing ship_mode") -> 17 | C5: Blanks replaced with "Unknown" and flagged.
A6: Discount | B6: =COUNTIF('Cleaned Orders'!AC:AC, "Missing Date") -> 0 | C6: Empty discounts treated as 0 (valid rows only).

Sheet 2. Duplicate Summary 
A1: Duplicate Record Summary
A3: Metric | B3: Record Count | C3: Logic Used
A4: Number of exact duplicate rows found | B4: 20 | C4: Rows where every single column matched identically.
A5: Number of duplicate order IDs found | B5: =COUNTIF('Cleaned Orders'!AC:AC, "Conflicting Duplicate Order ID") -> 63 | C5: Rows sharing an order_id but containing conflicting data fields.
A6: Number of records removed | B6: =B4 -> 20 | C6: Permanently removed exact duplicate rows from the final dataset.
A7: Number of records flagged for review | B7: =B5 -> 63 | C7: Retained in the final dataset but tagged for manual business logic resolution
A8: Logic used for handling duplicates | B8: Conditional Flagging | C8: Exact duplicates dropped entirely. Conflicting duplicates retained and flagged via COUNTIF matching to prevent data loss

Sheet 3. Invalid discount summary
A1: Invalid Discount Summary
A3: Out-of-Bounds Issue | B3: Count | C3: Rule Violation Definition
A4: Negative Discounts | B4: =COUNTIFS('Cleaned Orders'!P:P, "<0") -> 16 | C4: Any rate below 0.00% (Flagged as Invalid).
A5: Exceeded Max Threshold | B5: =COUNTIFS('Cleaned Orders'!P:P, ">0.7 OR >70%") -> 9 | C5: Discounts greater than 70% (Flagged as Invalid).

Sheet 4. Date issue summary
A1: Date Sequence Issue Summary
A3: Anomaly Identified | B3: Count | C3: Operational Impact
A4: Ship Date Before Order Date | B4: =COUNTIF('Cleaned Orders'!AC:AC, "Invalid shipping record") -> 69 | C4: Timeline logic failure (Flagged as Invalid shipping record).
A5: Unparseable / Text Dates | B5: =COUNTIF('Cleaned Orders'!AC:AC, "Text Value Not Recognized as Date") -> 247 | C5: Raw strings that Excel could not transform.

Sheet 5. Order status issue summary
A1: Order Status Impact Summary
A3: Order/Payment Status | B3: Volume | C3: Completed Sales Summary Action
A4: Cancelled | B4: =COUNTIF('Cleaned Orders'!U:U, "Cancelled") -> 146 | C4: Completely excluded from completed metrics.
A5: Failed Payments | B5: =COUNTIF('Cleaned Orders'!T:T, "Failed") -> 69 | C5: Completely excluded from completed metrics.
A6: Refunded / Returned | B6: =COUNTIF('Cleaned Orders'!U:U, "Returned") -> 164 | C6: Separately summarized as a distinct bucket.

Sheet 6. Sales-profit calculation
A1: Sales/Profit Calculation Mismatch Summary
A3: Calculation Check | B3: Variance Rows Found | C3: Status Notes
A4: Sales vs Calculated Sales | B4: =SUM('Cleaned Orders'!AD:AD) -> 65 | C4: Counts rows where raw sales don't match quantity * price.
A5: Profit vs Calculated Profit | B5: =SUM('Cleaned Orders'!AE:AE) -> 66 | C5: Counts rows where profit doesn't equal sales - cost.

Sheet 7. Final clean vs flagged 
A1: Final Dataset Quality Distribution
A3: Data Quality Classification | B3: Record Count | C3: Percentage of Total
A4: Valid (Clean Records) | B4: =COUNTIF('Cleaned Orders'!AC:AC, "Valid") -> 497 | C4: =B4/SUM(B4:B5)
A5: Flagged / Invalid Records | B5: =COUNTIF('Cleaned Orders'!AC:AC, "<>Valid") - 1 -> 1048078 | C5: =B5/SUM(B4:B5)
A6: Total Active Row Count | B6: =COUNTA('Cleaned Orders'!A:A) - 1 -> 932 | C6: 1

Sheet Cleaned Orders
A1: order_id | B1: order_date | C1: ship_date | D1: customer_id | E1: customer_name | F1: segment | G1: region | H1: state | I1: city | J1: category | K1: sub_category | L1: product_name | M1: ship_mode | N1: quantity | O1: unit_price | P1: discount | Q1: sales | R1: cost | S1: profit | T1: payment_status | U1: order_status | V1: cleaned_discount | W1: calculated_sales | X1: calculated_profit | Y1: profit_margin | Z1: shipping_delay_days | AA1: order_month | AB1: order_year | AC1: data_quality_flag | AD1: Sales Mismatch Check | AE1: Profit Mismatch Check | AH1: customer_name (cleaned) | AI1: segment (cleaned) | AJ1: region (cleaned) | AK1: state (cleaned) | AL1: city (cleaned) | AM1: category (cleaned) | AN1: sub_category (cleaned) | AO1: ship_mode (cleaned) | AP1: payment_status (cleaned) | AQ1: order_status (cleaned)
A2: ORD-2024-10001 | B2: 45494 | C2: 45500 | D2: CUST-4655 | E2: Karan Malhotra | F2: Consumer | G2: North | H2: Rajasthan | I2: Jaipur | J2: Office Supplies | K2: Paper | L2: Pro Paper 122 | M2: Second Class | N2: 8 | O2: 2976.45 | P2: 0.2 | Q2: 19049.28 | R2: 15841.89 | S2: 3207.39 | T2: Paid | U2: Completed | V2: =IF(ISBLANK(P2), 0, P2) -> 0.2 | W2: =N2 * O2 * (1 - P2) -> 19049.28 | X2: =W2-R2 -> 3207.39 | Y2: =IFERROR(X2 / W2, 0) -> 0.16837329 | Z2: =IF(OR(ISBLANK(B2), ISBLANK(C2), ISTEXT(B2), ISTEXT(C2)), "", C2 - B2) -> 6 | AA2: =MONTH(B2) -> 7 | AB2: =YEAR(B2) -> 2024 | AC2: =IF(COUNTIF(A:A, A2) > 1, "Conflicting Duplicate Order ID", IF(OR(G2="Unknown", ISBLANK(G2)), "Missing region", IF(OR(M2="Unknown", ISBLANK(M2)), "Missing ship_mode", IF(OR(ISBLANK(B2), ISBLANK(C2)), "Missing Date", IF(OR(ISTEXT(B2), ISTEXT(C2)), "Text Value Not Recognized as Date", IF(C2 < B2, "Invalid shipping record", IF(P2 < 0, "Invalid", IF(P2 > 0.7, "Invalid", "Valid")))))))) -> Valid | AD2: =IF(ABS(Q2 - W2) > 0.01, 1, 0) -> 0 | AE2: =IF(ABS(S2 - X2) > 0.01, 1, 0) -> 0 | AH2: =PROPER(TRIM(E2)) -> Karan Malhotra | AI2: =PROPER(TRIM(F2)) -> Consumer | AJ2: =PROPER(TRIM(G2)) -> North | AK2: =PROPER(TRIM(H2)) -> Rajasthan | AL2: =PROPER(TRIM(I2)) -> Jaipur | AM2: =PROPER(TRIM(J2)) -> Office Supplies | AN2: =PROPER(TRIM(K2)) -> Paper | AO2: =PROPER(TRIM(M2)) -> Second Class | AP2: =PROPER(TRIM(T2)) -> Paid | AQ2: =PROPER(TRIM(U2)) -> Completed
A3: ORD-2024-10002 | B3: 45535 | C3: 45540 | D3: CUST-2054 | E3: Mira Das | F3: Small Business | G3: East | H3: Odisha | I3: Bhubaneswar | J3: Furniture | K3: Tables | L3: Pro Tables 258 | M3: Same Day | N3: 3 | O3: 2437.5 | P3: 0 | Q3: 7312.5 | R3: 4904.73 | S3: 2407.77 | T3: Paid | U3: Completed | V3: =IF(ISBLANK(P3), 0, P3) -> 0 | W3: =N3 * O3 * (1 - P3) -> 7312.5 | X3: =W3-R3 -> 2407.77 | Y3: =IFERROR(X3 / W3, 0) -> 0.32926769 | Z3: =IF(OR(ISBLANK(B3), ISBLANK(C3), ISTEXT(B3), ISTEXT(C3)), "", C3 - B3) -> 5 | AA3: =MONTH(B3) -> 8 | AB3: =YEAR(B3) -> 2024 | AC3: =IF(COUNTIF(A:A, A3) > 1, "Conflicting Duplicate Order ID", IF(OR(G3="Unknown", ISBLANK(G3)), "Missing region", IF(OR(M3="Unknown", ISBLANK(M3)), "Missing ship_mode", IF(OR(ISBLANK(B3), ISBLANK(C3)), "Missing Date", IF(OR(ISTEXT(B3), ISTEXT(C3)), "Text Value Not Recognized as Date", IF(C3 < B3, "Invalid shipping record", IF(P3 < 0, "Invalid", IF(P3 > 0.7, "Invalid", "Valid")))))))) -> Valid | AD3: =IF(ABS(Q3 - W3) > 0.01, 1, 0) -> 0 | AE3: =IF(ABS(S3 - X3) > 0.01, 1, 0) -> 0 | AH3: =PROPER(TRIM(E3)) -> Mira Das | AI3: =PROPER(TRIM(F3)) -> Small Business | AJ3: =PROPER(TRIM(G3)) -> East | AK3: =PROPER(TRIM(H3)) -> Odisha | AL3: =PROPER(TRIM(I3)) -> Bhubaneswar | AM3: =PROPER(TRIM(J3)) -> Furniture | AN3: =PROPER(TRIM(K3)) -> Tables | AO3: =PROPER(TRIM(M3)) -> Same Day | AP3: =PROPER(TRIM(T3)) -> Paid | AQ3: =PROPER(TRIM(U3)) -> Completed
A4: ORD-2024-10003 | B4: 45451 | C4: 45458 | D4: CUST-6843 | E4: Isha Nair | F4: Consumer | G4: East | H4: Odisha | I4: Bhubaneswar | J4: Office Supplies | K4: Art | L4: Elite Art 525 | M4: First Class | N4: 4 | O4: 1065.43 | P4: 0.55 | Q4: 4261.72 | R4: 2465.69 | S4: 1796.03 | T4: Paid | U4: Completed | V4: =IF(ISBLANK(P4), 0, P4) -> 0.55 | W4: =N4 * O4 * (1 - P4) -> 1917.774 | X4: =W4-R4 -> -547.916 | Y4: =IFERROR(X4 / W4, 0) -> -0.28570415 | Z4: =IF(OR(ISBLANK(B4), ISBLANK(C4), ISTEXT(B4), ISTEXT(C4)), "", C4 - B4) -> 7 | AA4: =MONTH(B4) -> 6 | AB4: =YEAR(B4) -> 2024 | AC4: =IF(COUNTIF(A:A, A4) > 1, "Conflicting Duplicate Order ID", IF(OR(G4="Unknown", ISBLANK(G4)), "Missing region", IF(OR(M4="Unknown", ISBLANK(M4)), "Missing ship_mode", IF(OR(ISBLANK(B4), ISBLANK(C4)), "Missing Date", IF(OR(ISTEXT(B4), ISTEXT(C4)), "Text Value Not Recognized as Date", IF(C4 < B4, "Invalid shipping record", IF(P4 < 0, "Invalid", IF(P4 > 0.7, "Invalid", "Valid")))))))) -> Valid | AD4: =IF(ABS(Q4 - W4) > 0.01, 1, 0) -> 1 | AE4: =IF(ABS(S4 - X4) > 0.01, 1, 0) -> 1 | AH4: =PROPER(TRIM(E4)) -> Isha Nair | AI4: =PROPER(TRIM(F4)) -> Consumer | AJ4: =PROPER(TRIM(G4)) -> East | AK4: =PROPER(TRIM(H4)) -> Odisha | AL4: =PROPER(TRIM(I4)) -> Bhubaneswar | AM4: =PROPER(TRIM(J4)) -> Office Supplies | AN4: =PROPER(TRIM(K4)) -> Art | AO4: =PROPER(TRIM(M4)) -> First Class | AP4: =PROPER(TRIM(T4)) -> Paid | AQ4: =PROPER(TRIM(U4)) -> Completed
A5: ORD-2024-10004 | B5: 28-11-2024 | C5: 45625 | D5: CUST-3722 | E5: Arjun Bose | F5: Small Business | G5: South | H5: Telangana | I5: Hyderabad | J5: Furniture | K5: Furnishings | L5: Smart Furnishings 294 | M5: Standard Class | N5: 6 | O5: 1848.43 | P5: 0.25 | Q5: 8317.93 | R5: 6796.77 | S5: 1521.16 | T5: Paid | U5: Completed | V5: =IF(ISBLANK(P5), 0, P5) -> 0.25 | W5: =N5 * O5 * (1 - P5) -> 8317.935 | X5: =W5-R5 -> 1521.165 | Y5: =IFERROR(X5 / W5, 0) -> 0.18287772 | Z5: =IF(OR(ISBLANK(B5), ISBLANK(C5), ISTEXT(B5), ISTEXT(C5)), "", C5 - B5) | AA5: =MONTH(B5) -> #VALUE! | AB5: =YEAR(B5) -> #VALUE! | AC5: =IF(COUNTIF(A:A, A5) > 1, "Conflicting Duplicate Order ID", IF(OR(G5="Unknown", ISBLANK(G5)), "Missing region", IF(OR(M5="Unknown", ISBLANK(M5)), "Missing ship_mode", IF(OR(ISBLANK(B5), ISBLANK(C5)), "Missing Date", IF(OR(ISTEXT(B5), ISTEXT(C5)), "Text Value Not Recognized as Date", IF(C5 < B5, "Invalid shipping record", IF(P5 < 0, "Invalid", IF(P5 > 0.7, "Invalid", "Valid")))))))) -> Text Value Not Recognized as Date | AD5: =IF(ABS(Q5 - W5) > 0.01, 1, 0) -> 0 | AE5: =IF(ABS(S5 - X5) > 0.01, 1, 0) -> 0 | AH5: =PROPER(TRIM(E5)) -> Arjun Bose | AI5: =PROPER(TRIM(F5)) -> Small Business | AJ5: =PROPER(TRIM(G5)) -> South | AK5: =PROPER(TRIM(H5)) -> Telangana | AL5: =PROPER(TRIM(I5)) -> Hyderabad | AM5: =PROPER(TRIM(J5)) -> Furniture | AN5: =PROPER(TRIM(K5)) -> Furnishings | AO5: =PROPER(TRIM(M5)) -> Standard Class | AP5: =PROPER(TRIM(T5)) -> Paid | AQ5: =PROPER(TRIM(U5)) -> Completed
A6: ORD-2025-10005 | B6: 45898 | C6: 45901 | D6: CUST-8130 | E6: Ananya Rao | F6: Small Business | G6: West | H6: Maharashtra | I6: Mumbai | J6: Furniture | K6: Chairs | L6: Elite Chairs 543 | M6: First Class | N6: 7 | O6: 2973.76 | P6: 0 | Q6: 20816.32 | R6: 17705.37 | S6: 3110.95 | T6: Paid | U6: Cancelled | V6: =IF(ISBLANK(P6), 0, P6) -> 0 | W6: =N6 * O6 * (1 - P6) -> 20816.32 | X6: =W6-R6 -> 3110.95 | Y6: =IFERROR(X6 / W6, 0) -> 0.14944764 | Z6: =IF(OR(ISBLANK(B6), ISBLANK(C6), ISTEXT(B6), ISTEXT(C6)), "", C6 - B6) -> 3 | AA6: =MONTH(B6) -> 8 | AB6: =YEAR(B6) -> 2025 | AC6: =IF(COUNTIF(A:A, A6) > 1, "Conflicting Duplicate Order ID", IF(OR(G6="Unknown", ISBLANK(G6)), "Missing region", IF(OR(M6="Unknown", ISBLANK(M6)), "Missing ship_mode", IF(OR(ISBLANK(B6), ISBLANK(C6)), "Missing Date", IF(OR(ISTEXT(B6), ISTEXT(C6)), "Text Value Not Recognized as Date", IF(C6 < B6, "Invalid shipping record", IF(P6 < 0, "Invalid", IF(P6 > 0.7, "Invalid", "Valid")))))))) -> Valid | AD6: =IF(ABS(Q6 - W6) > 0.01, 1, 0) -> 0 | AE6: =IF(ABS(S6 - X6) > 0.01, 1, 0) -> 0 | AH6: =PROPER(TRIM(E6)) -> Ananya Rao | AI6: =PROPER(TRIM(F6)) -> Small Business | AJ6: =PROPER(TRIM(G6)) -> West | AK6: =PROPER(TRIM(H6)) -> Maharashtra | AL6: =PROPER(TRIM(I6)) -> Mumbai | AM6: =PROPER(TRIM(J6)) -> Furniture | AN6: =PROPER(TRIM(K6)) -> Chairs | AO6: =PROPER(TRIM(M6)) -> First Class | AP6: =PROPER(TRIM(T6)) -> Paid | AQ6: =PROPER(TRIM(U6)) -> Cancelled
A7: ORD-2024-10006 | B7: 45436 | C7: 28-05-2024 | D7: CUST-6056 | E7: Vikram Iyer | F7: Small Business | G7: West | H7: Madhya Pradesh | I7: Indore | J7: Technology | K7: Accessories | L7: Pro Accessories 821 | M7: Same Day | N7: 3 | O7: 1053.11 | P7: 0.2 | Q7: 2527.46 | R7: 1533.58 | S7: 993.88 | T7: Paid | U7: Completed | V7: =IF(ISBLANK(P7), 0, P7) -> 0.2 | W7: =N7 * O7 * (1 - P7) -> 2527.464 | X7: =W7-R7 -> 993.884 | Y7: =IFERROR(X7 / W7, 0) -> 0.39323369 | Z7: =IF(OR(ISBLANK(B7), ISBLANK(C7), ISTEXT(B7), ISTEXT(C7)), "", C7 - B7) | AA7: =MONTH(B7) -> 5 | AB7: =YEAR(B7) -> 2024 | AC7: =IF(COUNTIF(A:A, A7) > 1, "Conflicting Duplicate Order ID", IF(OR(G7="Unknown", ISBLANK(G7)), "Missing region", IF(OR(M7="Unknown", ISBLANK(M7)), "Missing ship_mode", IF(OR(ISBLANK(B7), ISBLANK(C7)), "Missing Date", IF(OR(ISTEXT(B7), ISTEXT(C7)), "Text Value Not Recognized as Date", IF(C7 < B7, "Invalid shipping record", IF(P7 < 0, "Invalid", IF(P7 > 0.7, "Invalid", "Valid")))))))) -> Text Value Not Recognized as Date | AD7: =IF(ABS(Q7 - W7) > 0.01, 1, 0) -> 0 | AE7: =IF(ABS(S7 - X7) > 0.01, 1, 0) -> 0 | AH7: =PROPER(TRIM(E7)) -> Vikram Iyer | AI7: =PROPER(TRIM(F7)) -> Small Business | AJ7: =PROPER(TRIM(G7)) -> West | AK7: =PROPER(TRIM(H7)) -> Madhya Pradesh | AL7: =PROPER(TRIM(I7)) -> Indore | AM7: =PROPER(TRIM(J7)) -> Technology | AN7: =PROPER(TRIM(K7)) -> Accessories | AO7: =PROPER(TRIM(M7)) -> Same Day | AP7: =PROPER(TRIM(T7)) -> Paid | AQ7: =PROPER(TRIM(U7)) -> Completed
A8: ORD-2025-10007 | B8: 45757 | C8: 45763 | D8: CUST-3656 | E8: Neha Gupta | F8: Consumer | G8: East | H8: Odisha | I8: Bhubaneswar | J8: Technology | K8: Copiers | L8: Eco Copiers 790 | M8: Standard Class | N8: 4 | O8: 1719.87 | P8: 0.15 | Q8: 5847.56 | R8: 4727.25 | S8: 1120.31 | T8: Paid | U8: Completed | V8: =IF(ISBLANK(P8), 0, P8) -> 0.15 | W8: =N8 * O8 * (1 - P8) -> 5847.558 | X8: =W8-R8 -> 1120.308 | Y8: =IFERROR(X8 / W8, 0) -> 0.19158562 | Z8: =IF(OR(ISBLANK(B8), ISBLANK(C8), ISTEXT(B8), ISTEXT(C8)), "", C8 - B8) -> 6 | AA8: =MONTH(B8) -> 4 | AB8: =YEAR(B8) -> 2025 | AC8: =IF(COUNTIF(A:A, A8) > 1, "Conflicting Duplicate Order ID", IF(OR(G8="Unknown", ISBLANK(G8)), "Missing region", IF(OR(M8="Unknown", ISBLANK(M8)), "Missing ship_mode", IF(OR(ISBLANK(B8), ISBLANK(C8)), "Missing Date", IF(OR(ISTEXT(B8), ISTEXT(C8)), "Text Value Not Recognized as Date", IF(C8 < B8, "Invalid shipping record", IF(P8 < 0, "Invalid", IF(P8 > 0.7, "Invalid", "Valid")))))))) -> Conflicting Duplicate Order ID | AD8: =IF(ABS(Q8 - W8) > 0.01, 1, 0) -> 0 | AE8: =IF(ABS(S8 - X8) > 0.01, 1, 0) -> 0 | AH8: =PROPER(TRIM(E8)) -> Neha Gupta | AI8: =PROPER(TRIM(F8)) -> Consumer | AJ8: =PROPER(TRIM(G8)) -> East | AK8: =PROPER(TRIM(H8)) -> Odisha | AL8: =PROPER(TRIM(I8)) -> Bhubaneswar | AM8: =PROPER(TRIM(J8)) -> Technology | AN8: =PROPER(TRIM(K8)) -> Copiers | AO8: =PROPER(TRIM(M8)) -> Standard Class | AP8: =PROPER(TRIM(T8)) -> Paid | AQ8: =PROPER(TRIM(U8)) -> Completed
A9: ORD-2025-10008 | B9: 45711 | C9: 26-02-2025 | D9: CUST-4683 | E9: Isha Nair | F9: Small Business | G9: South | H9: Andhra Pradesh | I9: Vijayawada | J9: Office Supplies | K9: Art | L9: Eco Art 848 | M9: First Class | N9: 1 | O9: 2980.71 | P9: 0 | Q9: 2980.71 | R9: 2357.22 | S9: 623.49 | T9: Paid | U9: Completed | V9: =IF(ISBLANK(P9), 0, P9) -> 0 | W9: =N9 * O9 * (1 - P9) -> 2980.71 | X9: =W9-R9 -> 623.49 | Y9: =IFERROR(X9 / W9, 0) -> 0.209175 | Z9: =IF(OR(ISBLANK(B9), ISBLANK(C9), ISTEXT(B9), ISTEXT(C9)), "", C9 - B9) | AA9: =MONTH(B9) -> 2 | AB9: =YEAR(B9) -> 2025 | AC9: =IF(COUNTIF(A:A, A9) > 1, "Conflicting Duplicate Order ID", IF(OR(G9="Unknown", ISBLANK(G9)), "Missing region", IF(OR(M9="Unknown", ISBLANK(M9)), "Missing ship_mode", IF(OR(ISBLANK(B9), ISBLANK(C9)), "Missing Date", IF(OR(ISTEXT(B9), ISTEXT(C9)), "Text Value Not Recognized as Date", IF(C9 < B9, "Invalid shipping record", IF(P9 < 0, "Invalid", IF(P9 > 0.7, "Invalid", "Valid")))))))) -> Text Value Not Recognized as Date | AD9: =IF(ABS(Q9 - W9) > 0.01, 1, 0) -> 0 | AE9: =IF(ABS(S9 - X9) > 0.01, 1, 0) -> 0 | AH9: =PROPER(TRIM(E9)) -> Isha Nair | AI9: =PROPER(TRIM(F9)) -> Small Business | AJ9: =PROPER(TRIM(G9)) -> South | AK9: =PROPER(TRIM(H9)) -> Andhra Pradesh | AL9: =PROPER(TRIM(I9)) -> Vijayawada | AM9: =PROPER(TRIM(J9)) -> Office Supplies | AN9: =PROPER(TRIM(K9)) -> Art | AO9: =PROPER(TRIM(M9)) -> First Class | AP9: =PROPER(TRIM(T9)) -> Paid | AQ9: =PROPER(TRIM(U9)) -> Completed
A10: ORD-2024-10009 | B10: 45601 | C10: 45606 | D10: CUST-2598 | E10: Aditi Sen | F10: Corporate | G10: South | H10: Telangana | I10: Hyderabad | J10: Office Supplies | K10: Labels | L10: Classic Labels 815 | M10: First Class | N10: 8 | O10: 3134.2 | P10: 0 | Q10: 25073.6 | R10: 17347.23 | S10: 7726.37 | T10: Paid | U10: Completed | V10: =IF(ISBLANK(P10), 0, P10) -> 0 | W10: =N10 * O10 * (1 - P10) -> 25073.6 | X10: =W10-R10 -> 7726.37 | Y10: =IFERROR(X10 / W10, 0) -> 0.30814761 | Z10: =IF(OR(ISBLANK(B10), ISBLANK(C10), ISTEXT(B10), ISTEXT(C10)), "", C10 - B10) -> 5 | AA10: =MONTH(B10) -> 11 | AB10: =YEAR(B10) -> 2024 | AC10: =IF(COUNTIF(A:A, A10) > 1, "Conflicting Duplicate Order ID", IF(OR(G10="Unknown", ISBLANK(G10)), "Missing region", IF(OR(M10="Unknown", ISBLANK(M10)), "Missing ship_mode", IF(OR(ISBLANK(B10), ISBLANK(C10)), "Missing Date", IF(OR(ISTEXT(B10), ISTEXT(C10)), "Text Value Not Recognized as Date", IF(C10 < B10, "Invalid shipping record", IF(P10 < 0, "Invalid", IF(P10 > 0.7, "Invalid", "Valid")))))))) -> Valid | AD10: =IF(ABS(Q10 - W10) > 0.01, 1, 0) -> 0 | AE10: =IF(ABS(S10 - X10) > 0.01, 1, 0) -> 0 | AH10: =PROPER(TRIM(E10)) -> Aditi Sen | AI10: =PROPER(TRIM(F10)) -> Corporate | AJ10: =PROPER(TRIM(G10)) -> South | AK10: =PROPER(TRIM(H10)) -> Telangana | AL10: =PROPER(TRIM(I10)) -> Hyderabad | AM10: =PROPER(TRIM(J10)) -> Office Supplies | AN10: =PROPER(TRIM(K10)) -> Labels | AO10: =PROPER(TRIM(M10)) -> First Class | AP10: =PROPER(TRIM(T10)) -> Paid | AQ10: =PROPER(TRIM(U10)) -> Completed
A11: ORD-2025-10010 | B11: 45847 | C11: 45912 | D11: CUST-2483 | E11: Mira Das | F11: Home Office | G11: South | H11: Telangana | I11: Hyderabad | J11: Office Supplies | K11: Paper | L11: Pro Paper 622 | M11: Second Class | N11: 9 | O11: 852.04 | P11: 0.2 | Q11: 6134.69 | R11: 3800.19 | S11: 2334.5 | T11: Paid | U11: Completed | V11: =IF(ISBLANK(P11), 0, P11) -> 0.2 | W11: =N11 * O11 * (1 - P11) -> 6134.688 | X11: =W11-R11 -> 2334.498 | Y11: =IFERROR(X11 / W11, 0) -> 0.38054062 | Z11: =IF(OR(ISBLANK(B11), ISBLANK(C11), ISTEXT(B11), ISTEXT(C11)), "", C11 - B11) -> 65 | AA11: =MONTH(B11) -> 7 | AB11: =YEAR(B11) -> 2025 | AC11: =IF(COUNTIF(A:A, A11) > 1, "Conflicting Duplicate Order ID", IF(OR(G11="Unknown", ISBLANK(G11)), "Missing region", IF(OR(M11="Unknown", ISBLANK(M11)), "Missing ship_mode", IF(OR(ISBLANK(B11), ISBLANK(C11)), "Missing Date", IF(OR(ISTEXT(B11), ISTEXT(C11)), "Text Value Not Recognized as Date", IF(C11 < B11, "Invalid shipping record", IF(P11 < 0, "Invalid", IF(P11 > 0.7, "Invalid", "Valid")))))))) -> Valid | AD11: =IF(ABS(Q11 - W11) > 0.01, 1, 0) -> 0 | AE11: =IF(ABS(S11 - X11) > 0.01, 1, 0) -> 0 | AH11: =PROPER(TRIM(E11)) -> Mira Das | AI11: =PROPER(TRIM(F11)) -> Home Office | AJ11: =PROPER(TRIM(G11)) -> South | AK11: =PROPER(TRIM(H11)) -> Telangana | AL11: =PROPER(TRIM(I11)) -> Hyderabad | AM11: =PROPER(TRIM(J11)) -> Office Supplies | AN11: =PROPER(TRIM(K11)) -> Paper | AO11: =PROPER(TRIM(M11)) -> Second Class | AP11: =PROPER(TRIM(T11)) -> Paid | AQ11: =PROPER(TRIM(U11)) -> Completed
A12: ORD-2025-10011 | B12: 45797 | C12: 45797 | D12: CUST-8092 | E12: Ananya Rao | F12: Corporate | G12: East | H12: West Bengal | I12: Kolkata | J12: Office Supplies | K12: Labels | L12: Prime Labels 644 | M12: Second Class | N12: 3 | O12: 3534.83 | P12: 0.05 | Q12: 10074.27 | R12: 6048.27 | S12: 4026 | T12: Refunded | U12: Returned | V12: =IF(ISBLANK(P12), 0, P12) -> 0.05 | W12: =N12 * O12 * (1 - P12) -> 10074.265 | X12: =W12-R12 -> 4025.9955 | Y12: =IFERROR(X12 / W12, 0) -> 0.39963167 | Z12: =IF(OR(ISBLANK(B12), ISBLANK(C12), ISTEXT(B12), ISTEXT(C12)), "", C12 - B12) -> 0 | AA12: =MONTH(B12) -> 5 | AB12: =YEAR(B12) -> 2025 | AC12: =IF(COUNTIF(A:A, A12) > 1, "Conflicting Duplicate Order ID", IF(OR(G12="Unknown", ISBLANK(G12)), "Missing region", IF(OR(M12="Unknown", ISBLANK(M12)), "Missing ship_mode", IF(OR(ISBLANK(B12), ISBLANK(C12)), "Missing Date", IF(OR(ISTEXT(B12), ISTEXT(C12)), "Text Value Not Recognized as Date", IF(C12 < B12, "Invalid shipping record", IF(P12 < 0, "Invalid", IF(P12 > 0.7, "Invalid", "Valid")))))))) -> Valid | AD12: =IF(ABS(Q12 - W12) > 0.01, 1, 0) -> 0 | AE12: =IF(ABS(S12 - X12) > 0.01, 1, 0) -> 0 | AH12: =PROPER(TRIM(E12)) -> Ananya Rao | AI12: =PROPER(TRIM(F12)) -> Corporate | AJ12: =PROPER(TRIM(G12)) -> East | AK12: =PROPER(TRIM(H12)) -> West Bengal | AL12: =PROPER(TRIM(I12)) -> Kolkata | AM12: =PROPER(TRIM(J12)) -> Office Supplies | AN12: =PROPER(TRIM(K12)) -> Labels | AO12: =PROPER(TRIM(M12)) -> Second Class | AP12: =PROPER(TRIM(T12)) -> Refunded | AQ12: =PROPER(TRIM(U12)) -> Returned
A13: ORD-2024-10012 | B13: 45495 | C13: 23-07-2024 | D13: CUST-6528 | E13: Vikram Iyer | F13: Small Business | G13: East | H13: Odisha | I13: Bhubaneswar | J13: Technology | K13: Accessories | L13: Smart Accessories 603 | M13: Same Day | N13: 6 | O13: 2005.95 | P13: 0.2 | Q13: 9628.56 | R13: 8038.59 | S13: 1589.97 | T13: Paid | U13: Completed | V13: =IF(ISBLANK(P13), 0, P13) -> 0.2 | W13: =N13 * O13 * (1 - P13) -> 9628.56 | X13: =W13-R13 -> 1589.97 | Y13: =IFERROR(X13 / W13, 0) -> 0.16513061 | Z13: =IF(OR(ISBLANK(B13), ISBLANK(C13), ISTEXT(B13), ISTEXT(C13)), "", C13 - B13) | AA13: =MONTH(B13) -> 7 | AB13: =YEAR(B13) -> 2024 | AC13: =IF(COUNTIF(A:A, A13) > 1, "Conflicting Duplicate Order ID", IF(OR(G13="Unknown", ISBLANK(G13)), "Missing region", IF(OR(M13="Unknown", ISBLANK(M13)), "Missing ship_mode", IF(OR(ISBLANK(B13), ISBLANK(C13)), "Missing Date", IF(OR(ISTEXT(B13), ISTEXT(C13)), "Text Value Not Recognized as Date", IF(C13 < B13, "Invalid shipping record", IF(P13 < 0, "Invalid", IF(P13 > 0.7, "Invalid", "Valid")))))))) -> Text Value Not Recognized as Date | AD13: =IF(ABS(Q13 - W13) > 0.01, 1, 0) -> 0 | AE13: =IF(ABS(S13 - X13) > 0.01, 1, 0) -> 0 | AH13: =PROPER(TRIM(E13)) -> Vikram Iyer | AI13: =PROPER(TRIM(F13)) -> Small Business | AJ13: =PROPER(TRIM(G13)) -> East | AK13: =PROPER(TRIM(H13)) -> Odisha | AL13: =PROPER(TRIM(I13)) -> Bhubaneswar | AM13: =PROPER(TRIM(J13)) -> Technology | AN13: =PROPER(TRIM(K13)) -> Accessories | AO13: =PROPER(TRIM(M13)) -> Same Day | AP13: =PROPER(TRIM(T13)) -> Paid | AQ13: =PROPER(TRIM(U13)) -> Completed
A14: ORD-2024-10013 | B14: 45646 | C14: 45647 | D14: CUST-2648 | E14: Ananya Rao | F14: Corporate | G14: West | H14: Rajasthan | I14: Udaipur | J14: Office Supplies | K14: Paper | L14: Pro Paper 481 | M14: First Class | N14: 1 | O14: 702.14 | P14: 0.15 | Q14: 596.82 | R14: 380.25 | S14: 216.57 | T14: Pending | U14: Returned | V14: =IF(ISBLANK(P14), 0, P14) -> 0.15 | W14: =N14 * O14 * (1 - P14) -> 596.819 | X14: =W14-R14 -> 216.569 | Y14: =IFERROR(X14 / W14, 0) -> 0.36287216 | Z14: =IF(OR(ISBLANK(B14), ISBLANK(C14), ISTEXT(B14), ISTEXT(C14)), "", C14 - B14) -> 1 | AA14: =MONTH(B14) -> 12 | AB14: =YEAR(B14) -> 2024 | AC14: =IF(COUNTIF(A:A, A14) > 1, "Conflicting Duplicate Order ID", IF(OR(G14="Unknown", ISBLANK(G14)), "Missing region", IF(OR(M14="Unknown", ISBLANK(M14)), "Missing ship_mode", IF(OR(ISBLANK(B14), ISBLANK(C14)), "Missing Date", IF(OR(ISTEXT(B14), ISTEXT(C14)), "Text Value Not Recognized as Date", IF(C14 < B14, "Invalid shipping record", IF(P14 < 0, "Invalid", IF(P14 > 0.7, "Invalid", "Valid")))))))) -> Valid | AD14: =IF(ABS(Q14 - W14) > 0.01, 1, 0) -> 0 | AE14: =IF(ABS(S14 - X14) > 0.01, 1, 0) -> 0 | AH14: =PROPER(TRIM(E14)) -> Ananya Rao | AI14: =PROPER(TRIM(F14)) -> Corporate | AJ14: =PROPER(TRIM(G14)) -> West | AK14: =PROPER(TRIM(H14)) -> Rajasthan | AL14: =PROPER(TRIM(I14)) -> Udaipur | AM14: =PROPER(TRIM(J14)) -> Office Supplies | AN14: =PROPER(TRIM(K14)) -> Paper | AO14: =PROPER(TRIM(M14)) -> First Class | AP14: =PROPER(TRIM(T14)) -> Pending | AQ14: =PROPER(TRIM(U14)) -> Returned
A15: ORD-2025-10014 | B15: 45942 | C15: 16-10-2025 | D15: CUST-7482 | E15: Priya Menon | F15: Small Business | G15: West | H15: Maharashtra | I15: Mumbai | J15: Office Supplies | K15: Art | L15: Smart Art 795 | M15: Second Class | N15: 7 | O15: 3964.72 | P15: 0.05 | Q15: 26365.39 | R15: 22306.24 | S15: 4059.15 | T15: Paid | U15: Completed | V15: =IF(ISBLANK(P15), 0, P15) -> 0.05 | W15: =N15 * O15 * (1 - P15) -> 26365.388 | X15: =W15-R15 -> 4059.148 | Y15: =IFERROR(X15 / W15, 0) -> 0.15395745 | Z15: =IF(OR(ISBLANK(B15), ISBLANK(C15), ISTEXT(B15), ISTEXT(C15)), "", C15 - B15) | AA15: =MONTH(B15) -> 10 | AB15: =YEAR(B15) -> 2025 | AC15: =IF(COUNTIF(A:A, A15) > 1, "Conflicting Duplicate Order ID", IF(OR(G15="Unknown", ISBLANK(G15)), "Missing region", IF(OR(M15="Unknown", ISBLANK(M15)), "Missing ship_mode", IF(OR(ISBLANK(B15), ISBLANK(C15)), "Missing Date", IF(OR(ISTEXT(B15), ISTEXT(C15)), "Text Value Not Recognized as Date", IF(C15 < B15, "Invalid shipping record", IF(P15 < 0, "Invalid", IF(P15 > 0.7, "Invalid", "Valid")))))))) -> Text Value Not Recognized as Date | AD15: =IF(ABS(Q15 - W15) > 0.01, 1, 0) -> 0 | AE15: =IF(ABS(S15 - X15) > 0.01, 1, 0) -> 0 | AH15: =PROPER(TRIM(E15)) -> Priya Menon | AI15: =PROPER(TRIM(F15)) -> Small Business | AJ15: =PROPER(TRIM(G15)) -> West | AK15: =PROPER(TRIM(H15)) -> Maharashtra | AL15: =PROPER(TRIM(I15)) -> Mumbai | AM15: =PROPER(TRIM(J15)) -> Office Supplies | AN15: =PROPER(TRIM(K15)) -> Art | AO15: =PROPER(TRIM(M15)) -> Second Class | AP15: =PROPER(TRIM(T15)) -> Paid | AQ15: =PROPER(TRIM(U15)) -> Completed
A16: ORD-2024-10015 | B16: 45653 | C16: 45654 | D16: CUST-4912 | E16: Rahul Verma | F16: Consumer | G16: West | H16: Rajasthan | I16: Udaipur | J16: Technology | K16: Copiers | L16: Max Copiers 983 | M16: Standard Class | N16: 2 | O16: 2737.83 | P16: 0.25 | Q16: 4106.74 | R16: 2666.3 | S16: 1440.44 | T16: Paid | U16: Completed | V16: =IF(ISBLANK(P16), 0, P16) -> 0.25 | W16: =N16 * O16 * (1 - P16) -> 4106.745 | X16: =W16-R16 -> 1440.445 | Y16: =IFERROR(X16 / W16, 0) -> 0.35075102 | Z16: =IF(OR(ISBLANK(B16), ISBLANK(C16), ISTEXT(B16), ISTEXT(C16)), "", C16 - B16) -> 1 | AA16: =MONTH(B16) -> 12 | AB16: =YEAR(B16) -> 2024 | AC16: =IF(COUNTIF(A:A, A16) > 1, "Conflicting Duplicate Order ID", IF(OR(G16="Unknown", ISBLANK(G16)), "Missing region", IF(OR(M16="Unknown", ISBLANK(M16)), "Missing ship_mode", IF(OR(ISBLANK(B16), ISBLANK(C16)), "Missing Date", IF(OR(ISTEXT(B16), ISTEXT(C16)), "Text Value Not Recognized as Date", IF(C16 < B16, "Invalid shipping record", IF(P16 < 0, "Invalid", IF(P16 > 0.7, "Invalid", "Valid")))))))) -> Valid | AD16: =IF(ABS(Q16 - W16) > 0.01, 1, 0) -> 0 | AE16: =IF(ABS(S16 - X16) > 0.01, 1, 0) -> 0 | AH16: =PROPER(TRIM(E16)) -> Rahul Verma | AI16: =PROPER(TRIM(F16)) -> Consumer | AJ16: =PROPER(TRIM(G16)) -> West | AK16: =PROPER(TRIM(H16)) -> Rajasthan | AL16: =PROPER(TRIM(I16)) -> Udaipur | AM16: =PROPER(TRIM(J16)) -> Technology | AN16: =PROPER(TRIM(K16)) -> Copiers | AO16: =PROPER(TRIM(M16)) -> Standard Class | AP16: =PROPER(TRIM(T16)) -> Paid | AQ16: =PROPER(TRIM(U16)) -> Completed
A17: ORD-2024-10016 | B17: 45482 | C17: 45482 | D17: CUST-7656 | E17: Karan Malhotra | F17: Small Business | G17: North | H17: Punjab | I17: Ludhiana | J17: Office Supplies | K17: Storage | L17: Classic Storage 198 | M17: Second Class | N17: 6 | O17: 3965.76 | P17: 0 | Q17: 23794.56 | R17: 15698.47 | S17: 8096.09 | T17: Paid | U17: Completed | V17: =IF(ISBLANK(P17), 0, P17) -> 0 | W17: =N17 * O17 * (1 - P17) -> 23794.56 | X17: =W17-R17 -> 8096.09 | Y17: =IFERROR(X17 / W17, 0) -> 0.34024962 | Z17: =IF(OR(ISBLANK(B17), ISBLANK(C17), ISTEXT(B17), ISTEXT(C17)), "", C17 - B17) -> 0 | AA17: =MONTH(B17) -> 7 | AB17: =YEAR(B17) -> 2024 | AC17: =IF(COUNTIF(A:A, A17) > 1, "Conflicting Duplicate Order ID", IF(OR(G17="Unknown", ISBLANK(G17)), "Missing region", IF(OR(M17="Unknown", ISBLANK(M17)), "Missing ship_mode", IF(OR(ISBLANK(B17), ISBLANK(C17)), "Missing Date", IF(OR(ISTEXT(B17), ISTEXT(C17)), "Text Value Not Recognized as Date", IF(C17 < B17, "Invalid shipping record", IF(P17 < 0, "Invalid", IF(P17 > 0.7, "Invalid", "Valid")))))))) -> Valid | AD17: =IF(ABS(Q17 - W17) > 0.01, 1, 0) -> 0 | AE17: =IF(ABS(S17 - X17) > 0.01, 1, 0) -> 0 | AH17: =PROPER(TRIM(E17)) -> Karan Malhotra | AI17: =PROPER(TRIM(F17)) -> Small Business | AJ17: =PROPER(TRIM(G17)) -> North | AK17: =PROPER(TRIM(H17)) -> Punjab | AL17: =PROPER(TRIM(I17)) -> Ludhiana | AM17: =PROPER(TRIM(J17)) -> Office Supplies | AN17: =PROPER(TRIM(K17)) -> Storage | AO17: =PROPER(TRIM(M17)) -> Second Class | AP17: =PROPER(TRIM(T17)) -> Paid | AQ17: =PROPER(TRIM(U17)) -> Completed
A18: ORD-2024-10017 | B18: 45420 | C18: 15-05-2024 | D18: CUST-6214 | E18: Aarav Sharma | F18: Consumer | G18: South | H18: Telangana | I18: Hyderabad | J18: Office Supplies | K18: Art | L18: Basic Art 204 | M18: First Class | N18: 4 | O18: 3323.51 | P18: 0.25 | Q18: 9970.53 | R18: 5668.17 | S18: 4302.36 | T18: Paid | U18: Completed | V18: =IF(ISBLANK(P18), 0, P18) -> 0.25 | W18: =N18 * O18 * (1 - P18) -> 9970.53 | X18: =W18-R18 -> 4302.36 | Y18: =IFERROR(X18 / W18, 0) -> 0.43150765 | Z18: =IF(OR(ISBLANK(B18), ISBLANK(C18), ISTEXT(B18), ISTEXT(C18)), "", C18 - B18) | AA18: =MONTH(B18) -> 5 | AB18: =YEAR(B18) -> 2024 | AC18: =IF(COUNTIF(A:A, A18) > 1, "Conflicting Duplicate Order ID", IF(OR(G18="Unknown", ISBLANK(G18)), "Missing region", IF(OR(M18="Unknown", ISBLANK(M18)), "Missing ship_mode", IF(OR(ISBLANK(B18), ISBLANK(C18)), "Missing Date", IF(OR(ISTEXT(B18), ISTEXT(C18)), "Text Value Not Recognized as Date", IF(C18 < B18, "Invalid shipping record", IF(P18 < 0, "Invalid", IF(P18 > 0.7, "Invalid", "Valid")))))))) -> Text Value Not Recognized as Date | AD18: =IF(ABS(Q18 - W18) > 0.01, 1, 0) -> 0 | AE18: =IF(ABS(S18 - X18) > 0.01, 1, 0) -> 0 | AH18: =PROPER(TRIM(E18)) -> Aarav Sharma | AI18: =PROPER(TRIM(F18)) -> Consumer | AJ18: =PROPER(TRIM(G18)) -> South | AK18: =PROPER(TRIM(H18)) -> Telangana | AL18: =PROPER(TRIM(I18)) -> Hyderabad | AM18: =PROPER(TRIM(J18)) -> Office Supplies | AN18: =PROPER(TRIM(K18)) -> Art | AO18: =PROPER(TRIM(M18)) -> First Class | AP18: =PROPER(TRIM(T18)) -> Paid | AQ18: =PROPER(TRIM(U18)) -> Completed
A19: ORD-2024-10018 | B19: 45298 | C19: 45299 | D19: CUST-1626 | E19: Sneha Kapoor | F19: Small Business | G19: North | H19: Rajasthan | I19: Jaipur | J19: Furniture | K19: Furnishings | L19: Basic Furnishings 434 | M19: Same Day | N19: 5 | O19: 1526.78 | P19: 0 | Q19: 7633.9 | R19: 4706.91 | S19: 2926.99 | T19: Paid | U19: Completed | V19: =IF(ISBLANK(P19), 0, P19) -> 0 | W19: =N19 * O19 * (1 - P19) -> 7633.9 | X19: =W19-R19 -> 2926.99 | Y19: =IFERROR(X19 / W19, 0) -> 0.38342001 | Z19: =IF(OR(ISBLANK(B19), ISBLANK(C19), ISTEXT(B19), ISTEXT(C19)), "", C19 - B19) -> 1 | AA19: =MONTH(B19) -> 1 | AB19: =YEAR(B19) -> 2024 | AC19: =IF(COUNTIF(A:A, A19) > 1, "Conflicting Duplicate Order ID", IF(OR(G19="Unknown", ISBLANK(G19)), "Missing region", IF(OR(M19="Unknown", ISBLANK(M19)), "Missing ship_mode", IF(OR(ISBLANK(B19), ISBLANK(C19)), "Missing Date", IF(OR(ISTEXT(B19), ISTEXT(C19)), "Text Value Not Recognized as Date", IF(C19 < B19, "Invalid shipping record", IF(P19 < 0, "Invalid", IF(P19 > 0.7, "Invalid", "Valid")))))))) -> Valid | AD19: =IF(ABS(Q19 - W19) > 0.01, 1, 0) -> 0 | AE19: =IF(ABS(S19 - X19) > 0.01, 1, 0) -> 0 | AH19: =PROPER(TRIM(E19)) -> Sneha Kapoor | AI19: =PROPER(TRIM(F19)) -> Small Business | AJ19: =PROPER(TRIM(G19)) -> North | AK19: =PROPER(TRIM(H19)) -> Rajasthan | AL19: =PROPER(TRIM(I19)) -> Jaipur | AM19: =PROPER(TRIM(J19)) -> Furniture | AN19: =PROPER(TRIM(K19)) -> Furnishings | AO19: =PROPER(TRIM(M19)) -> Same Day | AP19: =PROPER(TRIM(T19)) -> Paid | AQ19: =PROPER(TRIM(U19)) -> Completed
A20: ORD-2025-10019 | B20: 45853 | C20: 17-07-2025 | D20: CUST-2110 | E20: Aarav Sharma | F20: Home Office | G20: North | H20: Uttar Pradesh | I20: Noida | J20: Technology | K20: Copiers | L20: Eco Copiers 755 | M20: First Class | N20: 2 | O20: 1997.99 | P20: 0 | Q20: 3995.98 | R20: 2633.2 | S20: 1362.78 | T20: Refunded | U20: Cancelled | V20: =IF(ISBLANK(P20), 0, P20) -> 0 | W20: =N20 * O20 * (1 - P20) -> 3995.98 | X20: =W20-R20 -> 1362.78 | Y20: =IFERROR(X20 / W20, 0) -> 0.34103774 | Z20: =IF(OR(ISBLANK(B20), ISBLANK(C20), ISTEXT(B20), ISTEXT(C20)), "", C20 - B20) | AA20: =MONTH(B20) -> 7 | AB20: =YEAR(B20) -> 2025 | AC20: =IF(COUNTIF(A:A, A20) > 1, "Conflicting Duplicate Order ID", IF(OR(G20="Unknown", ISBLANK(G20)), "Missing region", IF(OR(M20="Unknown", ISBLANK(M20)), "Missing ship_mode", IF(OR(ISBLANK(B20), ISBLANK(C20)), "Missing Date", IF(OR(ISTEXT(B20), ISTEXT(C20)), "Text Value Not Recognized as Date", IF(C20 < B20, "Invalid shipping record", IF(P20 < 0, "Invalid", IF(P20 > 0.7, "Invalid", "Valid")))))))) -> Text Value Not Recognized as Date | AD20: =IF(ABS(Q20 - W20) > 0.01, 1, 0) -> 0 | AE20: =IF(ABS(S20 - X20) > 0.01, 1, 0) -> 0 | AH20: =PROPER(TRIM(E20)) -> Aarav Sharma | AI20: =PROPER(TRIM(F20)) -> Home Office | AJ20: =PROPER(TRIM(G20)) -> North | AK20: =PROPER(TRIM(H20)) -> Uttar Pradesh | AL20: =PROPER(TRIM(I20)) -> Noida | AM20: =PROPER(TRIM(J20)) -> Technology | AN20: =PROPER(TRIM(K20)) -> Copiers | AO20: =PROPER(TRIM(M20)) -> First Class | AP20: =PROPER(TRIM(T20)) -> Refunded | AQ20: =PROPER(TRIM(U20)) -> Cancelled
A21: ORD-2024-10020 | B21: 45500 | C21: 45504 | D21: CUST-3186 | E21: Rohan Mehta | F21: Home Office | G21: West | H21: Madhya Pradesh | I21: Indore | J21: Office Supplies | K21: Storage | L21: Prime Storage 121 | M21: Second Class | N21: 3 | O21: 3887.94 | P21: -0.19 | Q21: 9331.06 | R21: 7529.31 | S21: 1801.75 | T21: Paid | U21: Completed | V21: =IF(ISBLANK(P21), 0, P21) -> -0.19 | W21: =N21 * O21 * (1 - P21) -> 13879.946 | X21: =W21-R21 -> 6350.6358 | Y21: =IFERROR(X21 / W21, 0) -> 0.45754039 | Z21: =IF(OR(ISBLANK(B21), ISBLANK(C21), ISTEXT(B21), ISTEXT(C21)), "", C21 - B21) -> 4 | AA21: =MONTH(B21) -> 7 | AB21: =YEAR(B21) -> 2024 | AC21: =IF(COUNTIF(A:A, A21) > 1, "Conflicting Duplicate Order ID", IF(OR(G21="Unknown", ISBLANK(G21)), "Missing region", IF(OR(M21="Unknown", ISBLANK(M21)), "Missing ship_mode", IF(OR(ISBLANK(B21), ISBLANK(C21)), "Missing Date", IF(OR(ISTEXT(B21), ISTEXT(C21)), "Text Value Not Recognized as Date", IF(C21 < B21, "Invalid shipping record", IF(P21 < 0, "Invalid", IF(P21 > 0.7, "Invalid", "Valid")))))))) -> Invalid | AD21: =IF(ABS(Q21 - W21) > 0.01, 1, 0) -> 1 | AE21: =IF(ABS(S21 - X21) > 0.01, 1, 0) -> 1 | AH21: =PROPER(TRIM(E21)) -> Rohan Mehta | AI21: =PROPER(TRIM(F21)) -> Home Office | AJ21: =PROPER(TRIM(G21)) -> West | AK21: =PROPER(TRIM(H21)) -> Madhya Pradesh | AL21: =PROPER(TRIM(I21)) -> Indore | AM21: =PROPER(TRIM(J21)) -> Office Supplies | AN21: =PROPER(TRIM(K21)) -> Storage | AO21: =PROPER(TRIM(M21)) -> Second Class | AP21: =PROPER(TRIM(T21)) -> Paid | AQ21: =PROPER(TRIM(U21)) -> Completed
A22: ORD-2025-10021 | B22: 21-01-2025 | C22: 45680 | D22: CUST-3190 | E22: Aditi Sen | F22: Home Office | G22: East | H22: Bihar | I22: Patna | J22: Technology | K22: Copiers | L22: Elite Copiers 233 | M22: First Class | N22: 5 | O22: 4373.06 | P22: 0.25 | Q22: 16398.98 | R22: 9556.52 | S22: 6842.46 | T22: Paid | U22: Completed | V22: =IF(ISBLANK(P22), 0, P22) -> 0.25 | W22: =N22 * O22 * (1 - P22) -> 16398.975 | X22: =W22-R22 -> 6842.455 | Y22: =IFERROR(X22 / W22, 0) -> 0.41724894 | Z22: =IF(OR(ISBLANK(B22), ISBLANK(C22), ISTEXT(B22), ISTEXT(C22)), "", C22 - B22) | AA22: =MONTH(B22) -> #VALUE! | AB22: =YEAR(B22) -> #VALUE! | AC22: =IF(COUNTIF(A:A, A22) > 1, "Conflicting Duplicate Order ID", IF(OR(G22="Unknown", ISBLANK(G22)), "Missing region", IF(OR(M22="Unknown", ISBLANK(M22)), "Missing ship_mode", IF(OR(ISBLANK(B22), ISBLANK(C22)), "Missing Date", IF(OR(ISTEXT(B22), ISTEXT(C22)), "Text Value Not Recognized as Date", IF(C22 < B22, "Invalid shipping record", IF(P22 < 0, "Invalid", IF(P22 > 0.7, "Invalid", "Valid")))))))) -> Text Value Not Recognized as Date | AD22: =IF(ABS(Q22 - W22) > 0.01, 1, 0) -> 0 | AE22: =IF(ABS(S22 - X22) > 0.01, 1, 0) -> 0 | AH22: =PROPER(TRIM(E22)) -> Aditi Sen | AI22: =PROPER(TRIM(F22)) -> Home Office | AJ22: =PROPER(TRIM(G22)) -> East | AK22: =PROPER(TRIM(H22)) -> Bihar | AL22: =PROPER(TRIM(I22)) -> Patna | AM22: =PROPER(TRIM(J22)) -> Technology | AN22: =PROPER(TRIM(K22)) -> Copiers | AO22: =PROPER(TRIM(M22)) -> First Class | AP22: =PROPER(TRIM(T22)) -> Paid | AQ22: =PROPER(TRIM(U22)) -> Completed
A23: ORD-2025-10022 | B23: 24-01-2025 | C23: 45687 | D23: CUST-3036 | E23: Sneha Kapoor | F23: Consumer | G23: West | H23: Madhya Pradesh | I23: Indore | J23: Furniture | K23: Furnishings | L23: Eco Furnishings 897 | M23: Second Class | N23: 4 | O23: 697.69 | P23: -0.23 | Q23: 2790.76 | R23: 2037.71 | S23: 753.05 | T23: Paid | U23: Completed | V23: =IF(ISBLANK(P23), 0, P23) -> -0.23 | W23: =N23 * O23 * (1 - P23) -> 3432.6348 | X23: =W23-R23 -> 1394.9248 | Y23: =IFERROR(X23 / W23, 0) -> 0.40637146 | Z23: =IF(OR(ISBLANK(B23), ISBLANK(C23), ISTEXT(B23), ISTEXT(C23)), "", C23 - B23) | AA23: =MONTH(B23) -> #VALUE! | AB23: =YEAR(B23) -> #VALUE! | AC23: =IF(COUNTIF(A:A, A23) > 1, "Conflicting Duplicate Order ID", IF(OR(G23="Unknown", ISBLANK(G23)), "Missing region", IF(OR(M23="Unknown", ISBLANK(M23)), "Missing ship_mode", IF(OR(ISBLANK(B23), ISBLANK(C23)), "Missing Date", IF(OR(ISTEXT(B23), ISTEXT(C23)), "Text Value Not Recognized as Date", IF(C23 < B23, "Invalid shipping record", IF(P23 < 0, "Invalid", IF(P23 > 0.7, "Invalid", "Valid")))))))) -> Text Value Not Recognized as Date | AD23: =IF(ABS(Q23 - W23) > 0.01, 1, 0) -> 1 | AE23: =IF(ABS(S23 - X23) > 0.01, 1, 0) -> 1 | AH23: =PROPER(TRIM(E23)) -> Sneha Kapoor | AI23: =PROPER(TRIM(F23)) -> Consumer | AJ23: =PROPER(TRIM(G23)) -> West | AK23: =PROPER(TRIM(H23)) -> Madhya Pradesh | AL23: =PROPER(TRIM(I23)) -> Indore | AM23: =PROPER(TRIM(J23)) -> Furniture | AN23: =PROPER(TRIM(K23)) -> Furnishings | AO23: =PROPER(TRIM(M23)) -> Second Class | AP23: =PROPER(TRIM(T23)) -> Paid | AQ23: =PROPER(TRIM(U23)) -> Completed
A24: ORD-2025-10023 | B24: 45676 | C24: 45678 | D24: CUST-3588 | E24: Mira Das | F24: Consumer | G24: South | H24: Telangana | I24: Hyderabad | J24: Office Supplies | K24: Binders | L24: Max Binders 355 | M24: Standard Class | N24: 8 | O24: 1219.34 | P24: 0.15 | Q24: 8291.51 | R24: 6685.03 | S24: 1606.48 | T24: Failed | U24: Returned | V24: =IF(ISBLANK(P24), 0, P24) -> 0.15 | W24: =N24 * O24 * (1 - P24) -> 8291.512 | X24: =W24-R24 -> 1606.482 | Y24: =IFERROR(X24 / W24, 0) -> 0.19375019 | Z24: =IF(OR(ISBLANK(B24), ISBLANK(C24), ISTEXT(B24), ISTEXT(C24)), "", C24 - B24) -> 2 | AA24: =MONTH(B24) -> 1 | AB24: =YEAR(B24) -> 2025 | AC24: =IF(COUNTIF(A:A, A24) > 1, "Conflicting Duplicate Order ID", IF(OR(G24="Unknown", ISBLANK(G24)), "Missing region", IF(OR(M24="Unknown", ISBLANK(M24)), "Missing ship_mode", IF(OR(ISBLANK(B24), ISBLANK(C24)), "Missing Date", IF(OR(ISTEXT(B24), ISTEXT(C24)), "Text Value Not Recognized as Date", IF(C24 < B24, "Invalid shipping record", IF(P24 < 0, "Invalid", IF(P24 > 0.7, "Invalid", "Valid")))))))) -> Valid | AD24: =IF(ABS(Q24 - W24) > 0.01, 1, 0) -> 0 | AE24: =IF(ABS(S24 - X24) > 0.01, 1, 0) -> 0 | AH24: =PROPER(TRIM(E24)) -> Mira Das | AI24: =PROPER(TRIM(F24)) -> Consumer | AJ24: =PROPER(TRIM(G24)) -> South | AK24: =PROPER(TRIM(H24)) -> Telangana | AL24: =PROPER(TRIM(I24)) -> Hyderabad | AM24: =PROPER(TRIM(J24)) -> Office Supplies | AN24: =PROPER(TRIM(K24)) -> Binders | AO24: =PROPER(TRIM(M24)) -> Standard Class | AP24: =PROPER(TRIM(T24)) -> Failed | AQ24: =PROPER(TRIM(U24)) -> Returned
A25: ORD-2025-10024 | B25: 45898 | C25: 31-08-2025 | D25: CUST-7098 | E25: Rahul Verma | F25: Home Office | G25: East | H25: Bihar | I25: Patna | J25: Furniture | K25: Bookcases | L25: Pro Bookcases 394 | M25: First Class | N25: 4 | O25: 1958.01 | P25: 0.2 | Q25: 6265.63 | R25: 4321.86 | S25: 1943.77 | T25: Paid | U25: Completed | V25: =IF(ISBLANK(P25), 0, P25) -> 0.2 | W25: =N25 * O25 * (1 - P25) -> 6265.632 | X25: =W25-R25 -> 1943.772 | Y25: =IFERROR(X25 / W25, 0) -> 0.3102276 | Z25: =IF(OR(ISBLANK(B25), ISBLANK(C25), ISTEXT(B25), ISTEXT(C25)), "", C25 - B25) | AA25: =MONTH(B25) -> 8 | AB25: =YEAR(B25) -> 2025 | AC25: =IF(COUNTIF(A:A, A25) > 1, "Conflicting Duplicate Order ID", IF(OR(G25="Unknown", ISBLANK(G25)), "Missing region", IF(OR(M25="Unknown", ISBLANK(M25)), "Missing ship_mode", IF(OR(ISBLANK(B25), ISBLANK(C25)), "Missing Date", IF(OR(ISTEXT(B25), ISTEXT(C25)), "Text Value Not Recognized as Date", IF(C25 < B25, "Invalid shipping record", IF(P25 < 0, "Invalid", IF(P25 > 0.7, "Invalid", "Valid")))))))) -> Text Value Not Recognized as Date | AD25: =IF(ABS(Q25 - W25) > 0.01, 1, 0) -> 0 | AE25: =IF(ABS(S25 - X25) > 0.01, 1, 0) -> 0 | AH25: =PROPER(TRIM(E25)) -> Rahul Verma | AI25: =PROPER(TRIM(F25)) -> Home Office | AJ25: =PROPER(TRIM(G25)) -> East | AK25: =PROPER(TRIM(H25)) -> Bihar | AL25: =PROPER(TRIM(I25)) -> Patna | AM25: =PROPER(TRIM(J25)) -> Furniture | AN25: =PROPER(TRIM(K25)) -> Bookcases | AO25: =PROPER(TRIM(M25)) -> First Class | AP25: =PROPER(TRIM(T25)) -> Paid | AQ25: =PROPER(TRIM(U25)) -> Completed
A26: ORD-2024-10025 | B26: 45355 | C26: 45352 | D26: CUST-1747 | E26: Diya Patel | F26: Consumer | G26: North | H26: Punjab | I26: Ludhiana | J26: Office Supplies | K26: Art | L26: Max Art 215 | M26: Standard Class | N26: 4 | O26: 4492.94 | P26: 0.25 | Q26: 13478.82 | R26: 10937.35 | S26: 2541.47 | T26: Pending | U26: Cancelled | V26: =IF(ISBLANK(P26), 0, P26) -> 0.25 | W26: =N26 * O26 * (1 - P26) -> 13478.82 | X26: =W26-R26 -> 2541.47 | Y26: =IFERROR(X26 / W26, 0) -> 0.18855286 | Z26: =IF(OR(ISBLANK(B26), ISBLANK(C26), ISTEXT(B26), ISTEXT(C26)), "", C26 - B26) -> -3 | AA26: =MONTH(B26) -> 3 | AB26: =YEAR(B26) -> 2024 | AC26: =IF(COUNTIF(A:A, A26) > 1, "Conflicting Duplicate Order ID", IF(OR(G26="Unknown", ISBLANK(G26)), "Missing region", IF(OR(M26="Unknown", ISBLANK(M26)), "Missing ship_mode", IF(OR(ISBLANK(B26), ISBLANK(C26)), "Missing Date", IF(OR(ISTEXT(B26), ISTEXT(C26)), "Text Value Not Recognized as Date", IF(C26 < B26, "Invalid shipping record", IF(P26 < 0, "Invalid", IF(P26 > 0.7, "Invalid", "Valid")))))))) -> Invalid shipping record | AD26: =IF(ABS(Q26 - W26) > 0.01, 1, 0) -> 0 | AE26: =IF(ABS(S26 - X26) > 0.01, 1, 0) -> 0 | AH26: =PROPER(TRIM(E26)) -> Diya Patel | AI26: =PROPER(TRIM(F26)) -> Consumer | AJ26: =PROPER(TRIM(G26)) -> North | AK26: =PROPER(TRIM(H26)) -> Punjab | AL26: =PROPER(TRIM(I26)) -> Ludhiana | AM26: =PROPER(TRIM(J26)) -> Office Supplies | AN26: =PROPER(TRIM(K26)) -> Art | AO26: =PROPER(TRIM(M26)) -> Standard Class | AP26: =PROPER(TRIM(T26)) -> Pending | AQ26: =PROPER(TRIM(U26)) -> Cancelled
A27: ORD-2024-10026 | B27: 45606 | C27: 45584 | D27: CUST-1731 | E27: Arjun Bose | F27: Corporate | G27: East | H27: Assam | I27: Guwahati | J27: Technology | K27: Accessories | L27: Classic Accessories 478 | M27: First Class | N27: 2 | O27: 4315.2 | P27: 0.15 | Q27: 7335.84 | R27: 4968.41 | S27: 2367.43 | T27: Paid | U27: Completed | V27: =IF(ISBLANK(P27), 0, P27) -> 0.15 | W27: =N27 * O27 * (1 - P27) -> 7335.84 | X27: =W27-R27 -> 2367.43 | Y27: =IFERROR(X27 / W27, 0) -> 0.32272105 | Z27: =IF(OR(ISBLANK(B27), ISBLANK(C27), ISTEXT(B27), ISTEXT(C27)), "", C27 - B27) -> -22 | AA27: =MONTH(B27) -> 11 | AB27: =YEAR(B27) -> 2024 | AC27: =IF(COUNTIF(A:A, A27) > 1, "Conflicting Duplicate Order ID", IF(OR(G27="Unknown", ISBLANK(G27)), "Missing region", IF(OR(M27="Unknown", ISBLANK(M27)), "Missing ship_mode", IF(OR(ISBLANK(B27), ISBLANK(C27)), "Missing Date", IF(OR(ISTEXT(B27), ISTEXT(C27)), "Text Value Not Recognized as Date", IF(C27 < B27, "Invalid shipping record", IF(P27 < 0, "Invalid", IF(P27 > 0.7, "Invalid", "Valid")))))))) -> Invalid shipping record | AD27: =IF(ABS(Q27 - W27) > 0.01, 1, 0) -> 0 | AE27: =IF(ABS(S27 - X27) > 0.01, 1, 0) -> 0 | AH27: =PROPER(TRIM(E27)) -> Arjun Bose | AI27: =PROPER(TRIM(F27)) -> Corporate | AJ27: =PROPER(TRIM(G27)) -> East | AK27: =PROPER(TRIM(H27)) -> Assam | AL27: =PROPER(TRIM(I27)) -> Guwahati | AM27: =PROPER(TRIM(J27)) -> Technology | AN27: =PROPER(TRIM(K27)) -> Accessories | AO27: =PROPER(TRIM(M27)) -> First Class | AP27: =PROPER(TRIM(T27)) -> Paid | AQ27: =PROPER(TRIM(U27)) -> Completed
A28: ORD-2024-10027 | B28: 23-11-2024 | C28: 45619 | D28: CUST-4401 | E28: Diya Patel | F28: Corporate | G28: North | H28: Uttar Pradesh | I28: Noida | J28: Technology | K28: Phones | L28: Pro Phones 243 | M28: Standard Class | N28: 4 | O28: 716.13 | P28: 0.1 | Q28: 2578.07 | R28: 1527.55 | S28: 1050.52 | T28: Paid | U28: Returned | V28: =IF(ISBLANK(P28), 0, P28) -> 0.1 | W28: =N28 * O28 * (1 - P28) -> 2578.068 | X28: =W28-R28 -> 1050.518 | Y28: =IFERROR(X28 / W28, 0) -> 0.40748266 | Z28: =IF(OR(ISBLANK(B28), ISBLANK(C28), ISTEXT(B28), ISTEXT(C28)), "", C28 - B28) | AA28: =MONTH(B28) -> #VALUE! | AB28: =YEAR(B28) -> #VALUE! | AC28: =IF(COUNTIF(A:A, A28) > 1, "Conflicting Duplicate Order ID", IF(OR(G28="Unknown", ISBLANK(G28)), "Missing region", IF(OR(M28="Unknown", ISBLANK(M28)), "Missing ship_mode", IF(OR(ISBLANK(B28), ISBLANK(C28)), "Missing Date", IF(OR(ISTEXT(B28), ISTEXT(C28)), "Text Value Not Recognized as Date", IF(C28 < B28, "Invalid shipping record", IF(P28 < 0, "Invalid", IF(P28 > 0.7, "Invalid", "Valid")))))))) -> Text Value Not Recognized as Date | AD28: =IF(ABS(Q28 - W28) > 0.01, 1, 0) -> 0 | AE28: =IF(ABS(S28 - X28) > 0.01, 1, 0) -> 0 | AH28: =PROPER(TRIM(E28)) -> Diya Patel | AI28: =PROPER(TRIM(F28)) -> Corporate | AJ28: =PROPER(TRIM(G28)) -> North | AK28: =PROPER(TRIM(H28)) -> Uttar Pradesh | AL28: =PROPER(TRIM(I28)) -> Noida | AM28: =PROPER(TRIM(J28)) -> Technology | AN28: =PROPER(TRIM(K28)) -> Phones | AO28: =PROPER(TRIM(M28)) -> Standard Class | AP28: =PROPER(TRIM(T28)) -> Paid | AQ28: =PROPER(TRIM(U28)) -> Returned
A29: ORD-2025-10028 | B29: 45929 | C29: 45787 | D29: CUST-9875 | E29: Arjun Bose | F29: Small Business | G29: South | H29: Karnataka | I29: Bengaluru | J29: Office Supplies | K29: Paper | L29: Basic Paper 613 | M29: Second Class | N29: 5 | O29: 1806.51 | P29: 0.25 | Q29: 6774.41 | R29: 4710.36 | S29: 2064.05 | T29: Failed | U29: Returned | V29: =IF(ISBLANK(P29), 0, P29) -> 0.25 | W29: =N29 * O29 * (1 - P29) -> 6774.4125 | X29: =W29-R29 -> 2064.0525 | Y29: =IFERROR(X29 / W29, 0) -> 0.30468362 | Z29: =IF(OR(ISBLANK(B29), ISBLANK(C29), ISTEXT(B29), ISTEXT(C29)), "", C29 - B29) -> -142 | AA29: =MONTH(B29) -> 9 | AB29: =YEAR(B29) -> 2025 | AC29: =IF(COUNTIF(A:A, A29) > 1, "Conflicting Duplicate Order ID", IF(OR(G29="Unknown", ISBLANK(G29)), "Missing region", IF(OR(M29="Unknown", ISBLANK(M29)), "Missing ship_mode", IF(OR(ISBLANK(B29), ISBLANK(C29)), "Missing Date", IF(OR(ISTEXT(B29), ISTEXT(C29)), "Text Value Not Recognized as Date", IF(C29 < B29, "Invalid shipping record", IF(P29 < 0, "Invalid", IF(P29 > 0.7, "Invalid", "Valid")))))))) -> Invalid shipping record | AD29: =IF(ABS(Q29 - W29) > 0.01, 1, 0) -> 0 | AE29: =IF(ABS(S29 - X29) > 0.01, 1, 0) -> 0 | AH29: =PROPER(TRIM(E29)) -> Arjun Bose | AI29: =PROPER(TRIM(F29)) -> Small Business | AJ29: =PROPER(TRIM(G29)) -> South | AK29: =PROPER(TRIM(H29)) -> Karnataka | AL29: =PROPER(TRIM(I29)) -> Bengaluru | AM29: =PROPER(TRIM(J29)) -> Office Supplies | AN29: =PROPER(TRIM(K29)) -> Paper | AO29: =PROPER(TRIM(M29)) -> Second Class | AP29: =PROPER(TRIM(T29)) -> Failed | AQ29: =PROPER(TRIM(U29)) -> Returned
A30: ORD-2024-10029 | B30: 45606 | C30: 18-10-2024 | D30: CUST-1569 | E30: Ananya Rao | F30: Home Office | G30: West | H30: Gujarat | I30: Ahmedabad | J30: Technology | K30: Phones | L30: Prime Phones 698 | M30: Second Class | N30: 2 | O30: 1942.22 | P30: 0.25 | Q30: 2913.33 | R30: 2122.33 | S30: 791 | T30: Refunded | U30: Cancelled | V30: =IF(ISBLANK(P30), 0, P30) -> 0.25 | W30: =N30 * O30 * (1 - P30) -> 2913.33 | X30: =W30-R30 -> 791 | Y30: =IFERROR(X30 / W30, 0) -> 0.27151061 | Z30: =IF(OR(ISBLANK(B30), ISBLANK(C30), ISTEXT(B30), ISTEXT(C30)), "", C30 - B30) | AA30: =MONTH(B30) -> 11 | AB30: =YEAR(B30) -> 2024 | AC30: =IF(COUNTIF(A:A, A30) > 1, "Conflicting Duplicate Order ID", IF(OR(G30="Unknown", ISBLANK(G30)), "Missing region", IF(OR(M30="Unknown", ISBLANK(M30)), "Missing ship_mode", IF(OR(ISBLANK(B30), ISBLANK(C30)), "Missing Date", IF(OR(ISTEXT(B30), ISTEXT(C30)), "Text Value Not Recognized as Date", IF(C30 < B30, "Invalid shipping record", IF(P30 < 0, "Invalid", IF(P30 > 0.7, "Invalid", "Valid")))))))) -> Text Value Not Recognized as Date | AD30: =IF(ABS(Q30 - W30) > 0.01, 1, 0) -> 0 | AE30: =IF(ABS(S30 - X30) > 0.01, 1, 0) -> 0 | AH30: =PROPER(TRIM(E30)) -> Ananya Rao | AI30: =PROPER(TRIM(F30)) -> Home Office | AJ30: =PROPER(TRIM(G30)) -> West | AK30: =PROPER(TRIM(H30)) -> Gujarat | AL30: =PROPER(TRIM(I30)) -> Ahmedabad | AM30: =PROPER(TRIM(J30)) -> Technology | AN30: =PROPER(TRIM(K30)) -> Phones | AO30: =PROPER(TRIM(M30)) -> Second Class | AP30: =PROPER(TRIM(T30)) -> Refunded | AQ30: =PROPER(TRIM(U30)) -> Cancelled
A31: ORD-2025-10030 | B31: 45882 | C31: 13-08-2025 | D31: CUST-5936 | E31: Rohan Mehta | F31: Home Office | G31: South | H31: Kerala | I31: Kochi | J31: Technology | K31: Phones | L31: Pro Phones 442 | M31: Standard Class | N31: 1 | O31: 256.01 | P31: 0.15 | Q31: 217.61 | R31: 119.77 | S31: 97.84 | T31: Paid | U31: Completed | V31: =IF(ISBLANK(P31), 0, P31) -> 0.15 | W31: =N31 * O31 * (1 - P31) -> 217.6085 | X31: =W31-R31 -> 97.8385 | Y31: =IFERROR(X31 / W31, 0) -> 0.4496079 | Z31: =IF(OR(ISBLANK(B31), ISBLANK(C31), ISTEXT(B31), ISTEXT(C31)), "", C31 - B31) | AA31: =MONTH(B31) -> 8 | AB31: =YEAR(B31) -> 2025 | AC31: =IF(COUNTIF(A:A, A31) > 1, "Conflicting Duplicate Order ID", IF(OR(G31="Unknown", ISBLANK(G31)), "Missing region", IF(OR(M31="Unknown", ISBLANK(M31)), "Missing ship_mode", IF(OR(ISBLANK(B31), ISBLANK(C31)), "Missing Date", IF(OR(ISTEXT(B31), ISTEXT(C31)), "Text Value Not Recognized as Date", IF(C31 < B31, "Invalid shipping record", IF(P31 < 0, "Invalid", IF(P31 > 0.7, "Invalid", "Valid")))))))) -> Text Value Not Recognized as Date | AD31: =IF(ABS(Q31 - W31) > 0.01, 1, 0) -> 0 | AE31: =IF(ABS(S31 - X31) > 0.01, 1, 0) -> 0 | AH31: =PROPER(TRIM(E31)) -> Rohan Mehta | AI31: =PROPER(TRIM(F31)) -> Home Office | AJ31: =PROPER(TRIM(G31)) -> South | AK31: =PROPER(TRIM(H31)) -> Kerala | AL31: =PROPER(TRIM(I31)) -> Kochi | AM31: =PROPER(TRIM(J31)) -> Technology | AN31: =PROPER(TRIM(K31)) -> Phones | AO31: =PROPER(TRIM(M31)) -> Standard Class | AP31: =PROPER(TRIM(T31)) -> Paid | AQ31: =PROPER(TRIM(U31)) -> Completed
A32: ORD-2024-10031 | B32: 45331 | C32: 45334 | D32: CUST-8759 | E32: Ananya Rao | F32: Corporate | G32: West | H32: Goa | I32: Panaji | J32: Office Supplies | K32: Labels | L32: Pro Labels 355 | M32: First Class | N32: 1 | O32: 3421.77 | P32: 0.1 | Q32: 3079.59 | R32: 2001.89 | S32: 1077.7 | T32: Paid | U32: Completed | V32: =IF(ISBLANK(P32), 0, P32) -> 0.1 | W32: =N32 * O32 * (1 - P32) -> 3079.593 | X32: =W32-R32 -> 1077.703 | Y32: =IFERROR(X32 / W32, 0) -> 0.34994981 | Z32: =IF(OR(ISBLANK(B32), ISBLANK(C32), ISTEXT(B32), ISTEXT(C32)), "", C32 - B32) -> 3 | AA32: =MONTH(B32) -> 2 | AB32: =YEAR(B32) -> 2024 | AC32: =IF(COUNTIF(A:A, A32) > 1, "Conflicting Duplicate Order ID", IF(OR(G32="Unknown", ISBLANK(G32)), "Missing region", IF(OR(M32="Unknown", ISBLANK(M32)), "Missing ship_mode", IF(OR(ISBLANK(B32), ISBLANK(C32)), "Missing Date", IF(OR(ISTEXT(B32), ISTEXT(C32)), "Text Value Not Recognized as Date", IF(C32 < B32, "Invalid shipping record", IF(P32 < 0, "Invalid", IF(P32 > 0.7, "Invalid", "Valid")))))))) -> Valid | AD32: =IF(ABS(Q32 - W32) > 0.01, 1, 0) -> 0 | AE32: =IF(ABS(S32 - X32) > 0.01, 1, 0) -> 0 | AH32: =PROPER(TRIM(E32)) -> Ananya Rao | AI32: =PROPER(TRIM(F32)) -> Corporate | AJ32: =PROPER(TRIM(G32)) -> West | AK32: =PROPER(TRIM(H32)) -> Goa | AL32: =PROPER(TRIM(I32)) -> Panaji | AM32: =PROPER(TRIM(J32)) -> Office Supplies | AN32: =PROPER(TRIM(K32)) -> Labels | AO32: =PROPER(TRIM(M32)) -> First Class | AP32: =PROPER(TRIM(T32)) -> Paid | AQ32: =PROPER(TRIM(U32)) -> Completed
A33: ORD-2025-10032 | B33: 15-06-2025 | C33: 19-06-2025 | D33: CUST-7867 | E33: Karan Malhotra | F33: Small Business | G33: West | H33: Madhya Pradesh | I33: Indore | J33: Office Supplies | K33: Paper | L33: Pro Paper 959 | M33: Second Class | N33: 9 | O33: 3092.55 | P33: 0 | Q33: 27832.95 | R33: 17769.75 | S33: 10063.2 | T33: Failed | U33: Returned | V33: =IF(ISBLANK(P33), 0, P33) -> 0 | W33: =N33 * O33 * (1 - P33) -> 27832.95 | X33: =W33-R33 -> 10063.2 | Y33: =IFERROR(X33 / W33, 0) -> 0.36155708 | Z33: =IF(OR(ISBLANK(B33), ISBLANK(C33), ISTEXT(B33), ISTEXT(C33)), "", C33 - B33) | AA33: =MONTH(B33) -> #VALUE! | AB33: =YEAR(B33) -> #VALUE! | AC33: =IF(COUNTIF(A:A, A33) > 1, "Conflicting Duplicate Order ID", IF(OR(G33="Unknown", ISBLANK(G33)), "Missing region", IF(OR(M33="Unknown", ISBLANK(M33)), "Missing ship_mode", IF(OR(ISBLANK(B33), ISBLANK(C33)), "Missing Date", IF(OR(ISTEXT(B33), ISTEXT(C33)), "Text Value Not Recognized as Date", IF(C33 < B33, "Invalid shipping record", IF(P33 < 0, "Invalid", IF(P33 > 0.7, "Invalid", "Valid")))))))) -> Text Value Not Recognized as Date | AD33: =IF(ABS(Q33 - W33) > 0.01, 1, 0) -> 0 | AE33: =IF(ABS(S33 - X33) > 0.01, 1, 0) -> 0 | AH33: =PROPER(TRIM(E33)) -> Karan Malhotra | AI33: =PROPER(TRIM(F33)) -> Small Business | AJ33: =PROPER(TRIM(G33)) -> West | AK33: =PROPER(TRIM(H33)) -> Madhya Pradesh | AL33: =PROPER(TRIM(I33)) -> Indore | AM33: =PROPER(TRIM(J33)) -> Office Supplies | AN33: =PROPER(TRIM(K33)) -> Paper | AO33: =PROPER(TRIM(M33)) -> Second Class | AP33: =PROPER(TRIM(T33)) -> Failed | AQ33: =PROPER(TRIM(U33)) -> Returned
A34: ORD-2024-10033 | B34: 22-11-2024 | C34: 45622 | D34: CUST-6509 | E34: Aarav Sharma | F34: Corporate | G34: South | H34: Andhra Pradesh | I34: Vijayawada | J34: Technology | K34: Phones | L34: Basic Phones 242 | M34: Second Class | N34: 3 | O34: 4001.25 | Q34: 9002.81 | R34: 7529.92 | S34: 1472.89 | T34: Paid | U34: Completed | V34: =IF(ISBLANK(P34), 0, P34) -> 0 | W34: =N34 * O34 * (1 - P34) -> 12003.75 | X34: =W34-R34 -> 4473.83 | Y34: =IFERROR(X34 / W34, 0) -> 0.3727027 | Z34: =IF(OR(ISBLANK(B34), ISBLANK(C34), ISTEXT(B34), ISTEXT(C34)), "", C34 - B34) | AA34: =MONTH(B34) -> #VALUE! | AB34: =YEAR(B34) -> #VALUE! | AC34: =IF(COUNTIF(A:A, A34) > 1, "Conflicting Duplicate Order ID", IF(OR(G34="Unknown", ISBLANK(G34)), "Missing region", IF(OR(M34="Unknown", ISBLANK(M34)), "Missing ship_mode", IF(OR(ISBLANK(B34), ISBLANK(C34)), "Missing Date", IF(OR(ISTEXT(B34), ISTEXT(C34)), "Text Value Not Recognized as Date", IF(C34 < B34, "Invalid shipping record", IF(P34 < 0, "Invalid", IF(P34 > 0.7, "Invalid", "Valid")))))))) -> Text Value Not Recognized as Date | AD34: =IF(ABS(Q34 - W34) > 0.01, 1, 0) -> 1 | AE34: =IF(ABS(S34 - X34) > 0.01, 1, 0) -> 1 | AH34: =PROPER(TRIM(E34)) -> Aarav Sharma | AI34: =PROPER(TRIM(F34)) -> Corporate | AJ34: =PROPER(TRIM(G34)) -> South | AK34: =PROPER(TRIM(H34)) -> Andhra Pradesh | AL34: =PROPER(TRIM(I34)) -> Vijayawada | AM34: =PROPER(TRIM(J34)) -> Technology | AN34: =PROPER(TRIM(K34)) -> Phones | AO34: =PROPER(TRIM(M34)) -> Second Class | AP34: =PROPER(TRIM(T34)) -> Paid | AQ34: =PROPER(TRIM(U34)) -> Completed
A35: ORD-2024-10034 | B35: 45495 | C35: 27-07-2024 | D35: CUST-6660 | E35: Priya Menon | F35: Home Office | G35: West | H35: Goa | I35: Panaji | J35: Furniture | K35: Tables | L35: Max Tables 836 | M35: Same Day | N35: 7 | O35: 492.41 | P35: 0.25 | Q35: 2585.15 | R35: 2070.73 | S35: 514.42 | T35: Paid | U35: Completed | V35: =IF(ISBLANK(P35), 0, P35) -> 0.25 | W35: =N35 * O35 * (1 - P35) -> 2585.1525 | X35: =W35-R35 -> 514.4225 | Y35: =IFERROR(X35 / W35, 0) -> 0.19899116 | Z35: =IF(OR(ISBLANK(B35), ISBLANK(C35), ISTEXT(B35), ISTEXT(C35)), "", C35 - B35) | AA35: =MONTH(B35) -> 7 | AB35: =YEAR(B35) -> 2024 | AC35: =IF(COUNTIF(A:A, A35) > 1, "Conflicting Duplicate Order ID", IF(OR(G35="Unknown", ISBLANK(G35)), "Missing region", IF(OR(M35="Unknown", ISBLANK(M35)), "Missing ship_mode", IF(OR(ISBLANK(B35), ISBLANK(C35)), "Missing Date", IF(OR(ISTEXT(B35), ISTEXT(C35)), "Text Value Not Recognized as Date", IF(C35 < B35, "Invalid shipping record", IF(P35 < 0, "Invalid", IF(P35 > 0.7, "Invalid", "Valid")))))))) -> Text Value Not Recognized as Date | AD35: =IF(ABS(Q35 - W35) > 0.01, 1, 0) -> 0 | AE35: =IF(ABS(S35 - X35) > 0.01, 1, 0) -> 0 | AH35: =PROPER(TRIM(E35)) -> Priya Menon | AI35: =PROPER(TRIM(F35)) -> Home Office | AJ35: =PROPER(TRIM(G35)) -> West | AK35: =PROPER(TRIM(H35)) -> Goa | AL35: =PROPER(TRIM(I35)) -> Panaji | AM35: =PROPER(TRIM(J35)) -> Furniture | AN35: =PROPER(TRIM(K35)) -> Tables | AO35: =PROPER(TRIM(M35)) -> Same Day | AP35: =PROPER(TRIM(T35)) -> Paid | AQ35: =PROPER(TRIM(U35)) -> Completed
A36: ORD-2025-10035 | B36: 45688 | C36: 45693 | D36: CUST-2392 | E36: Priya Menon | F36: Home Office | G36: East | H36: West Bengal | I36: Kolkata | J36: Furniture | K36: Chairs | L36: Elite Chairs 862 | N36: 2 | O36: 4159.69 | P36: 0.2 | Q36: 6655.5 | R36: 4340.21 | S36: 2607.32 | T36: Paid | U36: Completed | V36: =IF(ISBLANK(P36), 0, P36) -> 0.2 | W36: =N36 * O36 * (1 - P36) -> 6655.504 | X36: =W36-R36 -> 2315.294 | Y36: =IFERROR(X36 / W36, 0) -> 0.34787658 | Z36: =IF(OR(ISBLANK(B36), ISBLANK(C36), ISTEXT(B36), ISTEXT(C36)), "", C36 - B36) -> 5 | AA36: =MONTH(B36) -> 1 | AB36: =YEAR(B36) -> 2025 | AC36: =IF(COUNTIF(A:A, A36) > 1, "Conflicting Duplicate Order ID", IF(OR(G36="Unknown", ISBLANK(G36)), "Missing region", IF(OR(M36="Unknown", ISBLANK(M36)), "Missing ship_mode", IF(OR(ISBLANK(B36), ISBLANK(C36)), "Missing Date", IF(OR(ISTEXT(B36), ISTEXT(C36)), "Text Value Not Recognized as Date", IF(C36 < B36, "Invalid shipping record", IF(P36 < 0, "Invalid", IF(P36 > 0.7, "Invalid", "Valid")))))))) -> Missing ship_mode | AD36: =IF(ABS(Q36 - W36) > 0.01, 1, 0) -> 0 | AE36: =IF(ABS(S36 - X36) > 0.01, 1, 0) -> 1 | AH36: =PROPER(TRIM(E36)) -> Priya Menon | AI36: =PROPER(TRIM(F36)) -> Home Office | AJ36: =PROPER(TRIM(G36)) -> East | AK36: =PROPER(TRIM(H36)) -> West Bengal | AL36: =PROPER(TRIM(I36)) -> Kolkata | AM36: =PROPER(TRIM(J36)) -> Furniture | AN36: =PROPER(TRIM(K36)) -> Chairs | AO36: Unknown | AP36: =PROPER(TRIM(T36)) -> Paid | AQ36: =PROPER(TRIM(U36)) -> Completed
A37: ORD-2024-10036 | B37: 29-05-2024 | C37: 45441 | D37: CUST-1611 | E37: Sneha Kapoor | F37: Small Business | G37: West | H37: Gujarat | I37: Ahmedabad | J37: Furniture | K37: Bookcases | L37: Prime Bookcases 414 | M37: Second Class | N37: 8 | O37: 2507.12 | P37: 0.05 | Q37: 19054.11 | R37: 15313.83 | S37: 3740.28 | T37: Pending | U37: Returned | V37: =IF(ISBLANK(P37), 0, P37) -> 0.05 | W37: =N37 * O37 * (1 - P37) -> 19054.112 | X37: =W37-R37 -> 3740.282 | Y37: =IFERROR(X37 / W37, 0) -> 0.19629789 | Z37: =IF(OR(ISBLANK(B37), ISBLANK(C37), ISTEXT(B37), ISTEXT(C37)), "", C37 - B37) | AA37: =MONTH(B37) -> #VALUE! | AB37: =YEAR(B37) -> #VALUE! | AC37: =IF(COUNTIF(A:A, A37) > 1, "Conflicting Duplicate Order ID", IF(OR(G37="Unknown", ISBLANK(G37)), "Missing region", IF(OR(M37="Unknown", ISBLANK(M37)), "Missing ship_mode", IF(OR(ISBLANK(B37), ISBLANK(C37)), "Missing Date", IF(OR(ISTEXT(B37), ISTEXT(C37)), "Text Value Not Recognized as Date", IF(C37 < B37, "Invalid shipping record", IF(P37 < 0, "Invalid", IF(P37 > 0.7, "Invalid", "Valid")))))))) -> Text Value Not Recognized as Date | AD37: =IF(ABS(Q37 - W37) > 0.01, 1, 0) -> 0 | AE37: =IF(ABS(S37 - X37) > 0.01, 1, 0) -> 0 | AH37: =PROPER(TRIM(E37)) -> Sneha Kapoor | AI37: =PROPER(TRIM(F37)) -> Small Business | AJ37: =PROPER(TRIM(G37)) -> West | AK37: =PROPER(TRIM(H37)) -> Gujarat | AL37: =PROPER(TRIM(I37)) -> Ahmedabad | AM37: =PROPER(TRIM(J37)) -> Furniture | AN37: =PROPER(TRIM(K37)) -> Bookcases | AO37: =PROPER(TRIM(M37)) -> Second Class | AP37: =PROPER(TRIM(T37)) -> Pending | AQ37: =PROPER(TRIM(U37)) -> Returned
